Workbook

Sheet Vocabulary
A1: HSK level | B1: Hanzi | C1: Pinyin | D1: English meaning | E1: Character | F1: Tone
A2: 1 | B2: 爱 | C2: ài | D2: love | E2: 爱 ài (Ø+AI) | F2: 4
A3: 1 | B3: 八 | C3: bā | D3: eight | E3: 八 bā (B+A) | F3: 1
A4: 1 | B4: 爸爸 | C4: bàba | D4: dad; father | E4: 爸 bà (B+A) · 爸 ba (B+A) | F4: 4-5
A5: 1 | B5: 杯子 | C5: bēizi | D5: cup; glass | E5: 杯 bēi (B+EI) · 子 zi (Z+Ø (no final)) | F5: 1-5
A6: 1 | B6: 北京 | C6: Běijīng | D6: Beijing | E6: 北 běi (B+EI) · 京 jīng (J+ING) | F6: 3-1
A7: 1 | B7: 本 | C7: běn | D7: measure word for books | E7: 本 běn (B+(E)N) | F7: 3
A8: 1 | B8: 不客气 | C8: bú kèqi | D8: you're welcome | E8: 不 bú (B+U) · 客 kè (K+E) · 气 qi (Q+I) | F8: 2-4-5
A9: 1 | B9: 不 | C9: bù | D9: no; not | E9: 不 bù (B+U) | F9: 4
A10: 1 | B10: 菜 | C10: cài | D10: dish; vegetable | E10: 菜 cài (C+AI) | F10: 4
A11: 1 | B11: 茶 | C11: chá | D11: tea | E11: 茶 chá (CH+A) | F11: 2
A12: 1 | B12: 吃 | C12: chī | D12: eat | E12: 吃 chī (CH+Ø (no final)) | F12: 1
A13: 1 | B13: 出租车 | C13: chūzūchē | D13: taxi | E13: 出 chū (CH+U) · 租 zū (Z+U) · 车 chē (CH+E) | F13: 1-1-1
... A601: 3 | B601: 作业 | C601: zuò yè | D601: homework | E601: 作 zuò (Z+UO) · 业 yè (Y+E) | F601: 4-4

Sheet Unique Hanzi
A1: Hanzi | B1: First HSK level | C1: Pinyin | D1: Tone | E1: Initial | F1: Final | G1: Actor | H1: Location | I1: Tone area | J1: HMM status | K1: Other readings in list | L1: Appears in | N1: 617 unique characters
A2: 爱 | B2: 1 | C2: ài | D2: 4 | E2: Ø | F2: AI | G2: =IFERROR(IF(INDEX('HMM Actors'!$B:$B,MATCH(E2,'HMM Actors'!$A:$A,0))="","(not assigned)",INDEX('HMM Actors'!$B:$B,MATCH(E2,'HMM Actors'!$A:$A,0))),"(not assigned)") | H2: =IFERROR(IF(INDEX('HMM Locations'!$B:$B,MATCH(F2,'HMM Locations'!$A:$A,0))="","(not assigned)",INDEX('HMM Locations'!$B:$B,MATCH(F2,'HMM Locations'!$A:$A,0))),"(not assigned)") | I2: =IFERROR(IF(INDEX('HMM Locations'!$C:$G,MATCH(F2,'HMM Locations'!$A:$A,0),D2)="","(not assigned)",INDEX('HMM Locations'!$C:$G,MATCH(F2,'HMM Locations'!$A:$A,0),D2)),"(not assigned)") | J2: =IF(COUNTIF(G2:I2,"(not assigned)")=0,"Ready","Needs grid entry") | L2: 爱、爱好、可爱 | N2: Distinct simplified Hanzi appearing in the 600 entries; punctuation excluded.
A3: 八 | B3: 1 | C3: bā | D3: 1 | E3: B | F3: A | G3: =IFERROR(IF(INDEX('HMM Actors'!$B:$B,MATCH(E3,'HMM Actors'!$A:$A,0))="","(not assigned)",INDEX('HMM Actors'!$B:$B,MATCH(E3,'HMM Actors'!$A:$A,0))),"(not assigned)") | H3: =IFERROR(IF(INDEX('HMM Locations'!$B:$B,MATCH(F3,'HMM Locations'!$A:$A,0))="","(not assigned)",INDEX('HMM Locations'!$B:$B,MATCH(F3,'HMM Locations'!$A:$A,0))),"(not assigned)") | I3: =IFERROR(IF(INDEX('HMM Locations'!$C:$G,MATCH(F3,'HMM Locations'!$A:$A,0),D3)="","(not assigned)",INDEX('HMM Locations'!$C:$G,MATCH(F3,'HMM Locations'!$A:$A,0),D3)),"(not assigned)") | J3: =IF(COUNTIF(G3:I3,"(not assigned)")=0,"Ready","Needs grid entry") | L3: 八 | N3: Pinyin is each character's main reading, taken from the words in the Vocabulary sheet (一 and 不 use their citation tones). Tone 5 = neutral. Initial/Final follow the HMM grid's spelling rules: y- and w- count as initials, and zhi/chi/shi/ri/zi/ci/si use the Ø final.
A4: 爸 | B4: 1 | C4: bà | D4: 4 | E4: B | F4: A | G4: =IFERROR(IF(INDEX('HMM Actors'!$B:$B,MATCH(E4,'HMM Actors'!$A:$A,0))="","(not assigned)",INDEX('HMM Actors'!$B:$B,MATCH(E4,'HMM Actors'!$A:$A,0))),"(not assigned)") | H4: =IFERROR(IF(INDEX('HMM Locations'!$B:$B,MATCH(F4,'HMM Locations'!$A:$A,0))="","(not assigned)",INDEX('HMM Locations'!$B:$B,MATCH(F4,'HMM Locations'!$A:$A,0))),"(not assigned)") | I4: =IFERROR(IF(INDEX('HMM Locations'!$C:$G,MATCH(F4,'HMM Locations'!$A:$A,0),D4)="","(not assigned)",INDEX('HMM Locations'!$C:$G,MATCH(F4,'HMM Locations'!$A:$A,0),D4)),"(not assigned)") | J4: =IF(COUNTIF(G4:I4,"(not assigned)")=0,"Ready","Needs grid entry") | L4: 爸爸 | N4: Actor, Location and Tone area are formulas that read the HMM Actors and HMM Locations sheets.
A5: 杯 | B5: 1 | C5: bēi | D5: 1 | E5: B | F5: EI | G5: =IFERROR(IF(INDEX('HMM Actors'!$B:$B,MATCH(E5,'HMM Actors'!$A:$A,0))="","(not assigned)",INDEX('HMM Actors'!$B:$B,MATCH(E5,'HMM Actors'!$A:$A,0))),"(not assigned)") | H5: =IFERROR(IF(INDEX('HMM Locations'!$B:$B,MATCH(F5,'HMM Locations'!$A:$A,0))="","(not assigned)",INDEX('HMM Locations'!$B:$B,MATCH(F5,'HMM Locations'!$A:$A,0))),"(not assigned)") | I5: =IFERROR(IF(INDEX('HMM Locations'!$C:$G,MATCH(F5,'HMM Locations'!$A:$A,0),D5)="","(not assigned)",INDEX('HMM Locations'!$C:$G,MATCH(F5,'HMM Locations'!$A:$A,0),D5)),"(not assigned)") | J5: =IF(COUNTIF(G5:I5,"(not assigned)")=0,"Ready","Needs grid entry") | L5: 杯子
A6: 北 | B6: 1 | C6: běi | D6: 3 | E6: B | F6: EI | G6: =IFERROR(IF(INDEX('HMM Actors'!$B:$B,MATCH(E6,'HMM Actors'!$A:$A,0))="","(not assigned)",INDEX('HMM Actors'!$B:$B,MATCH(E6,'HMM Actors'!$A:$A,0))),"(not assigned)") | H6: =IFERROR(IF(INDEX('HMM Locations'!$B:$B,MATCH(F6,'HMM Locations'!$A:$A,0))="","(not assigned)",INDEX('HMM Locations'!$B:$B,MATCH(F6,'HMM Locations'!$A:$A,0))),"(not assigned)") | I6: =IFERROR(IF(INDEX('HMM Locations'!$C:$G,MATCH(F6,'HMM Locations'!$A:$A,0),D6)="","(not assigned)",INDEX('HMM Locations'!$C:$G,MATCH(F6,'HMM Locations'!$A:$A,0),D6)),"(not assigned)") | J6: =IF(COUNTIF(G6:I6,"(not assigned)")=0,"Ready","Needs grid entry") | L6: 北京、北方
A7: 本 | B7: 1 | C7: běn | D7: 3 | E7: B | F7: (E)N | G7: =IFERROR(IF(INDEX('HMM Actors'!$B:$B,MATCH(E7,'HMM Actors'!$A:$A,0))="","(not assigned)",INDEX('HMM Actors'!$B:$B,MATCH(E7,'HMM Actors'!$A:$A,0))),"(not assigned)") | H7: =IFERROR(IF(INDEX('HMM Locations'!$B:$B,MATCH(F7,'HMM Locations'!$A:$A,0))="","(not assigned)",INDEX('HMM Locations'!$B:$B,MATCH(F7,'HMM Locations'!$A:$A,0))),"(not assigned)") | I7: =IFERROR(IF(INDEX('HMM Locations'!$C:$G,MATCH(F7,'HMM Locations'!$A:$A,0),D7)="","(not assigned)",INDEX('HMM Locations'!$C:$G,MATCH(F7,'HMM Locations'!$A:$A,0),D7)),"(not assigned)") | J7: =IF(COUNTIF(G7:I7,"(not assigned)")=0,"Ready","Needs grid entry") | L7: 本、笔记本
A8: 不 | B8: 1 | C8: bù | D8: 4 | E8: B | F8: U | G8: =IFERROR(IF(INDEX('HMM Actors'!$B:$B,MATCH(E8,'HMM Actors'!$A:$A,0))="","(not assigned)",INDEX('HMM Actors'!$B:$B,MATCH(E8,'HMM Actors'!$A:$A,0))),"(not assigned)") | H8: =IFERROR(IF(INDEX('HMM Locations'!$B:$B,MATCH(F8,'HMM Locations'!$A:$A,0))="","(not assigned)",INDEX('HMM Locations'!$B:$B,MATCH(F8,'HMM Locations'!$A:$A,0))),"(not assigned)") | I8: =IFERROR(IF(INDEX('HMM Locations'!$C:$G,MATCH(F8,'HMM Locations'!$A:$A,0),D8)="","(not assigned)",INDEX('HMM Locations'!$C:$G,MATCH(F8,'HMM Locations'!$A:$A,0),D8)),"(not assigned)") | J8: =IF(COUNTIF(G8:I8,"(not assigned)")=0,"Ready","Needs grid entry") | K8: bú | L8: 不客气、不、对不起、不但…而且…
A9: 菜 | B9: 1 | C9: cài | D9: 4 | E9: C | F9: AI | G9: =IFERROR(IF(INDEX('HMM Actors'!$B:$B,MATCH(E9,'HMM Actors'!$A:$A,0))="","(not assigned)",INDEX('HMM Actors'!$B:$B,MATCH(E9,'HMM Actors'!$A:$A,0))),"(not assigned)") | H9: =IFERROR(IF(INDEX('HMM Locations'!$B:$B,MATCH(F9,'HMM Locations'!$A:$A,0))="","(not assigned)",INDEX('HMM Locations'!$B:$B,MATCH(F9,'HMM Locations'!$A:$A,0))),"(not assigned)") | I9: =IFERROR(IF(INDEX('HMM Locations'!$C:$G,MATCH(F9,'HMM Locations'!$A:$A,0),D9)="","(not assigned)",INDEX('HMM Locations'!$C:$G,MATCH(F9,'HMM Locations'!$A:$A,0),D9)),"(not assigned)") | J9: =IF(COUNTIF(G9:I9,"(not assigned)")=0,"Ready","Needs grid entry") | L9: 菜、菜单
A10: 茶 | B10: 1 | C10: chá | D10: 2 | E10: CH | F10: A | G10: =IFERROR(IF(INDEX('HMM Actors'!$B:$B,MATCH(E10,'HMM Actors'!$A:$A,0))="","(not assigned)",INDEX('HMM Actors'!$B:$B,MATCH(E10,'HMM Actors'!$A:$A,0))),"(not assigned)") | H10: =IFERROR(IF(INDEX('HMM Locations'!$B:$B,MATCH(F10,'HMM Locations'!$A:$A,0))="","(not assigned)",INDEX('HMM Locations'!$B:$B,MATCH(F10,'HMM Locations'!$A:$A,0))),"(not assigned)") | I10: =IFERROR(IF(INDEX('HMM Locations'!$C:$G,MATCH(F10,'HMM Locations'!$A:$A,0),D10)="","(not assigned)",INDEX('HMM Locations'!$C:$G,MATCH(F10,'HMM Locations'!$A:$A,0),D10)),"(not assigned)") | J10: =IF(COUNTIF(G10:I10,"(not assigned)")=0,"Ready","Needs grid entry") | L10: 茶
A11: 车 | B11: 1 | C11: chē | D11: 1 | E11: CH | F11: E | G11: =IFERROR(IF(INDEX('HMM Actors'!$B:$B,MATCH(E11,'HMM Actors'!$A:$A,0))="","(not assigned)",INDEX('HMM Actors'!$B:$B,MATCH(E11,'HMM Actors'!$A:$A,0))),"(not assigned)") | H11: =IFERROR(IF(INDEX('HMM Locations'!$B:$B,MATCH(F11,'HMM Locations'!$A:$A,0))="","(not assigned)",INDEX('HMM Locations'!$B:$B,MATCH(F11,'HMM Locations'!$A:$A,0))),"(not assigned)") | I11: =IFERROR(IF(INDEX('HMM Locations'!$C:$G,MATCH(F11,'HMM Locations'!$A:$A,0),D11)="","(not assigned)",INDEX('HMM Locations'!$C:$G,MATCH(F11,'HMM Locations'!$A:$A,0),D11)),"(not assigned)") | J11: =IF(COUNTIF(G11:I11,"(not assigned)")=0,"Ready","Needs grid entry") | L11: 出租车、公共汽车、火车站、自行车
A12: 吃 | B12: 1 | C12: chī | D12: 1 | E12: CH | F12: Ø (no final) | G12: =IFERROR(IF(INDEX('HMM Actors'!$B:$B,MATCH(E12,'HMM Actors'!$A:$A,0))="","(not assigned)",INDEX('HMM Actors'!$B:$B,MATCH(E12,'HMM Actors'!$A:$A,0))),"(not assigned)") | H12: =IFERROR(IF(INDEX('HMM Locations'!$B:$B,MATCH(F12,'HMM Locations'!$A:$A,0))="","(not assigned)",INDEX('HMM Locations'!$B:$B,MATCH(F12,'HMM Locations'!$A:$A,0))),"(not assigned)") | I12: =IFERROR(IF(INDEX('HMM Locations'!$C:$G,MATCH(F12,'HMM Locations'!$A:$A,0),D12)="","(not assigned)",INDEX('HMM Locations'!$C:$G,MATCH(F12,'HMM Locations'!$A:$A,0),D12)),"(not assigned)") | J12: =IF(COUNTIF(G12:I12,"(not assigned)")=0,"Ready","Needs grid entry") | L12: 吃、好吃
A13: 出 | B13: 1 | C13: chū | D13: 1 | E13: CH | F13: U | G13: =IFERROR(IF(INDEX('HMM Actors'!$B:$B,MATCH(E13,'HMM Actors'!$A:$A,0))="","(not assigned)",INDEX('HMM Actors'!$B:$B,MATCH(E13,'HMM Actors'!$A:$A,0))),"(not assigned)") | H13: =IFERROR(IF(INDEX('HMM Locations'!$B:$B,MATCH(F13,'HMM Locations'!$A:$A,0))="","(not assigned)",INDEX('HMM Locations'!$B:$B,MATCH(F13,'HMM Locations'!$A:$A,0))),"(not assigned)") | I13: =IFERROR(IF(INDEX('HMM Locations'!$C:$G,MATCH(F13,'HMM Locations'!$A:$A,0),D13)="","(not assigned)",INDEX('HMM Locations'!$C:$G,MATCH(F13,'HMM Locations'!$A:$A,0),D13)),"(not assigned)") | J13: =IF(COUNTIF(G13:I13,"(not assigned)")=0,"Ready","Needs grid entry") | L13: 出租车、出
A14: 打 | B14: 1 | C14: dǎ | D14: 3 | E14: D | F14: A | G14: =IFERROR(IF(INDEX('HMM Actors'!$B:$B,MATCH(E14,'HMM Actors'!$A:$A,0))="","(not assigned)",INDEX('HMM Actors'!$B:$B,MATCH(E14,'HMM Actors'!$A:$A,0))),"(not assigned)") | H14: =IFERROR(IF(INDEX('HMM Locations'!$B:$B,MATCH(F14,'HMM Locations'!$A:$A,0))="","(not assigned)",INDEX('HMM Locations'!$B:$B,MATCH(F14,'HMM Locations'!$A:$A,0))),"(not assigned)") | I14: =IFERROR(IF(INDEX('HMM Locations'!$C:$G,MATCH(F14,'HMM Locations'!$A:$A,0),D14)="","(not assigned)",INDEX('HMM Locations'!$C:$G,MATCH(F14,'HMM Locations'!$A:$A,0),D14)),"(not assigned)") | J14: =IF(COUNTIF(G14:I14,"(not assigned)")=0,"Ready","Needs grid entry") | L14: 打电话、打篮球、打扫、打算
A15: 大 | B15: 1 | C15: dà | D15: 4 | E15: D | F15: A | G15: =IFERROR(IF(INDEX('HMM Actors'!$B:$B,MATCH(E15,'HMM Actors'!$A:$A,0))="","(not assigned)",INDEX('HMM Actors'!$B:$B,MATCH(E15,'HMM Actors'!$A:$A,0))),"(not assigned)") | H15: =IFERROR(IF(INDEX('HMM Locations'!$B:$B,MATCH(F15,'HMM Locations'!$A:$A,0))="","(not assigned)",INDEX('HMM Locations'!$B:$B,MATCH(F15,'HMM Locations'!$A:$A,0))),"(not assigned)") | I15: =IFERROR(IF(INDEX('HMM Locations'!$C:$G,MATCH(F15,'HMM Locations'!$A:$A,0),D15)="","(not assigned)",INDEX('HMM Locations'!$C:$G,MATCH(F15,'HMM Locations'!$A:$A,0),D15)),"(not assigned)") | J15: =IF(COUNTIF(G15:I15,"(not assigned)")=0,"Ready","Needs grid entry") | L15: 大、大家
A16: 的 | B16: 1 | C16: de | D16: 5 | E16: D | F16: E | G16: =IFERROR(IF(INDEX('HMM Actors'!$B:$B,MATCH(E16,'HMM Actors'!$A:$A,0))="","(not assigned)",INDEX('HMM Actors'!$B:$B,MATCH(E16,'HMM Actors'!$A:$A,0))),"(not assigned)") | H16: =IFERROR(IF(INDEX('HMM Locations'!$B:$B,MATCH(F16,'HMM Locations'!$A:$A,0))="","(not assigned)",INDEX('HMM Locations'!$B:$B,MATCH(F16,'HMM Locations'!$A:$A,0))),"(not assigned)") | I16: =IFERROR(IF(INDEX('HMM Locations'!$C:$G,MATCH(F16,'HMM Locations'!$A:$A,0),D16)="","(not assigned)",INDEX('HMM Locations'!$C:$G,MATCH(F16,'HMM Locations'!$A:$A,0),D16)),"(not assigned)") | J16: =IF(COUNTIF(G16:I16,"(not assigned)")=0,"Ready","Needs grid entry") | L16: 的
A17: 点 | B17: 1 | C17: diǎn | D17: 3 | E17: D | F17: IAN | G17: =IFERROR(IF(INDEX('HMM Actors'!$B:$B,MATCH(E17,'HMM Actors'!$A:$A,0))="","(not assigned)",INDEX('HMM Actors'!$B:$B,MATCH(E17,'HMM Actors'!$A:$A,0))),"(not assigned)") | H17: =IFERROR(IF(INDEX('HMM Locations'!$B:$B,MATCH(F17,'HMM Locations'!$A:$A,0))="","(not assigned)",INDEX('HMM Locations'!$B:$B,MATCH(F17,'HMM Locations'!$A:$A,0))),"(not assigned)") | I17: =IFERROR(IF(INDEX('HMM Locations'!$C:$G,MATCH(F17,'HMM Locations'!$A:$A,0),D17)="","(not assigned)",INDEX('HMM Locations'!$C:$G,MATCH(F17,'HMM Locations'!$A:$A,0),D17)),"(not assigned)") | J17: =IF(COUNTIF(G17:I17,"(not assigned)")=0,"Ready","Needs grid entry") | L17: 点、一点儿
A18: 电 | B18: 1 | C18: diàn | D18: 4 | E18: D | F18: IAN | G18: =IFERROR(IF(INDEX('HMM Actors'!$B:$B,MATCH(E18,'HMM Actors'!$A:$A,0))="","(not assigned)",INDEX('HMM Actors'!$B:$B,MATCH(E18,'HMM Actors'!$A:$A,0))),"(not assigned)") | H18: =IFERROR(IF(INDEX('HMM Locations'!$B:$B,MATCH(F18,'HMM Locations'!$A:$A,0))="","(not assigned)",INDEX('HMM Locations'!$B:$B,MATCH(F18,'HMM Locations'!$A:$A,0))),"(not assigned)") | I18: =IFERROR(IF(INDEX('HMM Locations'!$C:$G,MATCH(F18,'HMM Locations'!$A:$A,0),D18)="","(not assigned)",INDEX('HMM Locations'!$C:$G,MATCH(F18,'HMM Locations'!$A:$A,0),D18)),"(not assigned)") | J18: =IF(COUNTIF(G18:I18,"(not assigned)")=0,"Ready","Needs grid entry") | L18: 打电话、电脑、电视、电影
A19: 店 | B19: 1 | C19: diàn | D19: 4 | E19: D | F19: IAN | G19: =IFERROR(IF(INDEX('HMM Actors'!$B:$B,MATCH(E19,'HMM Actors'!$A:$A,0))="","(not assigned)",INDEX('HMM Actors'!$B:$B,MATCH(E19,'HMM Actors'!$A:$A,0))),"(not assigned)") | H19: =IFERROR(IF(INDEX('HMM Locations'!$B:$B,MATCH(F19,'HMM Locations'!$A:$A,0))="","(not assigned)",INDEX('HMM Locations'!$B:$B,MATCH(F19,'HMM Locations'!$A:$A,0))),"(not assigned)") | I19: =IFERROR(IF(INDEX('HMM Locations'!$C:$G,MATCH(F19,'HMM Locations'!$A:$A,0),D19)="","(not assigned)",INDEX('HMM Locations'!$C:$G,MATCH(F19,'HMM Locations'!$A:$A,0),D19)),"(not assigned)") | J19: =IF(COUNTIF(G19:I19,"(not assigned)")=0,"Ready","Needs grid entry") | L19: 饭店、商店
A20: 东 | B20: 1 | C20: dōng | D20: 1 | E20: D | F20: ONG | G20: =IFERROR(IF(INDEX('HMM Actors'!$B:$B,MATCH(E20,'HMM Actors'!$A:$A,0))="","(not assigned)",INDEX('HMM Actors'!$B:$B,MATCH(E20,'HMM Actors'!$A:$A,0))),"(not assigned)") | H20: =IFERROR(IF(INDEX('HMM Locations'!$B:$B,MATCH(F20,'HMM Locations'!$A:$A,0))="","(not assigned)",INDEX('HMM Locations'!$B:$B,MATCH(F20,'HMM Locations'!$A:$A,0))),"(not assigned)") | I20: =IFERROR(IF(INDEX('HMM Locations'!$C:$G,MATCH(F20,'HMM Locations'!$A:$A,0),D20)="","(not assigned)",INDEX('HMM Locations'!$C:$G,MATCH(F20,'HMM Locations'!$A:$A,0),D20)),"(not assigned)") | J20: =IF(COUNTIF(G20:I20,"(not assigned)")=0,"Ready","Needs grid entry") | L20: 东西、东
... A38: 汉 | B38: 1 | C38: hàn | D38: 4 | E38: H | F38: AN | G38: =IFERROR(IF(INDEX('HMM Actors'!$B:$B,MATCH(E38,'HMM Actors'!$A:$A,0))="","(not assigned)",INDEX('HMM Actors'!$B:$B,MATCH(E38,'HMM Actors'!$A:$A,0))),"(not assigned)") | H38: =IFERROR(IF(INDEX('HMM Locations'!$B:$B,MATCH(F38,'HMM Locations'!$A:$A,0))="","(not assigned)",INDEX('HMM Locations'!$B:$B,MATCH(F38,'HMM Locations'!$A:$A,0))),"(not assigned)") | I38: =IFERROR(IF(INDEX('HMM Locations'!$C:$G,MATCH(F38,'HMM Locations'!$A:$A,0),D38)="","(not assigned)",INDEX('HMM Locations'!$C:$G,MATCH(F38,'HMM Locations'!$A:$A,0),D38)),"(not assigned)") | J38: =IF(COUNTIF(G38:I38,"(not assigned)")=0,"Ready","Needs grid entry") | L38: 汉语
A39: 好 | B39: 1 | C39: hǎo | D39: 3 | E39: H | F39: AO | G39: =IFERROR(IF(INDEX('HMM Actors'!$B:$B,MATCH(E39,'HMM Actors'!$A:$A,0))="","(not assigned)",INDEX('HMM Actors'!$B:$B,MATCH(E39,'HMM Actors'!$A:$A,0))),"(not assigned)") | H39: =IFERROR(IF(INDEX('HMM Locations'!$B:$B,MATCH(F39,'HMM Locations'!$A:$A,0))="","(not assigned)",INDEX('HMM Locations'!$B:$B,MATCH(F39,'HMM Locations'!$A:$A,0))),"(not assigned)") | I39: =IFERROR(IF(INDEX('HMM Locations'!$C:$G,MATCH(F39,'HMM Locations'!$A:$A,0),D39)="","(not assigned)",INDEX('HMM Locations'!$C:$G,MATCH(F39,'HMM Locations'!$A:$A,0),D39)),"(not assigned)") | J39: =IF(COUNTIF(G39:I39,"(not assigned)")=0,"Ready","Needs grid entry") | K39: hào | L39: 好、好吃、爱好
A40: 号 | B40: 1 | C40: hào | D40: 4 | E40: H | F40: AO | G40: =IFERROR(IF(INDEX('HMM Actors'!$B:$B,MATCH(E40,'HMM Actors'!$A:$A,0))="","(not assigned)",INDEX('HMM Actors'!$B:$B,MATCH(E40,'HMM Actors'!$A:$A,0))),"(not assigned)") | H40: =IFERROR(IF(INDEX('HMM Locations'!$B:$B,MATCH(F40,'HMM Locations'!$A:$A,0))="","(not assigned)",INDEX('HMM Locations'!$B:$B,MATCH(F40,'HMM Locations'!$A:$A,0))),"(not assigned)") | I40: =IFERROR(IF(INDEX('HMM Locations'!$C:$G,MATCH(F40,'HMM Locations'!$A:$A,0),D40)="","(not assigned)",INDEX('HMM Locations'!$C:$G,MATCH(F40,'HMM Locations'!$A:$A,0),D40)),"(not assigned)") | J40: =IF(COUNTIF(G40:I40,"(not assigned)")=0,"Ready","Needs grid entry") | L40: 号
A41: 喝 | B41: 1 | C41: hē | D41: 1 | E41: H | F41: E | G41: =IFERROR(IF(INDEX('HMM Actors'!$B:$B,MATCH(E41,'HMM Actors'!$A:$A,0))="","(not assigned)",INDEX('HMM Actors'!$B:$B,MATCH(E41,'HMM Actors'!$A:$A,0))),"(not assigned)") | H41: =IFERROR(IF(INDEX('HMM Locations'!$B:$B,MATCH(F41,'HMM Locations'!$A:$A,0))="","(not assigned)",INDEX('HMM Locations'!$B:$B,MATCH(F41,'HMM Locations'!$A:$A,0))),"(not assigned)") | I41: =IFERROR(IF(INDEX('HMM Locations'!$C:$G,MATCH(F41,'HMM Locations'!$A:$A,0),D41)="","(not assigned)",INDEX('HMM Locations'!$C:$G,MATCH(F41,'HMM Locations'!$A:$A,0),D41)),"(not assigned)") | J41: =IF(COUNTIF(G41:I41,"(not assigned)")=0,"Ready","Needs grid entry") | L41: 喝
A42: 和 | B42: 1 | C42: hé | D42: 2 | E42: H | F42: E | G42: =IFERROR(IF(INDEX('HMM Actors'!$B:$B,MATCH(E42,'HMM Actors'!$A:$A,0))="","(not assigned)",INDEX('HMM Actors'!$B:$B,MATCH(E42,'HMM Actors'!$A:$A,0))),"(not assigned)") | H42: =IFERROR(IF(INDEX('HMM Locations'!$B:$B,MATCH(F42,'HMM Locations'!$A:$A,0))="","(not assigned)",INDEX('HMM Locations'!$B:$B,MATCH(F42,'HMM Locations'!$A:$A,0))),"(not assigned)") | I42: =IFERROR(IF(INDEX('HMM Locations'!$C:$G,MATCH(F42,'HMM Locations'!$A:$A,0),D42)="","(not assigned)",INDEX('HMM Locations'!$C:$G,MATCH(F42,'HMM Locations'!$A:$A,0),D42)),"(not assigned)") | J42: =IF(COUNTIF(G42:I42,"(not assigned)")=0,"Ready","Needs grid entry") | L42: 和
A43: 很 | B43: 1 | C43: hěn | D43: 3 | E43: H | F43: (E)N | G43: =IFERROR(IF(INDEX('HMM Actors'!$B:$B,MATCH(E43,'HMM Actors'!$A:$A,0))="","(not assigned)",INDEX('HMM Actors'!$B:$B,MATCH(E43,'HMM Actors'!$A:$A,0))),"(not assigned)") | H43: =IFERROR(IF(INDEX('HMM Locations'!$B:$B,MATCH(F43,'HMM Locations'!$A:$A,0))="","(not assigned)",INDEX('HMM Locations'!$B:$B,MATCH(F43,'HMM Locations'!$A:$A,0))),"(not assigned)") | I43: =IFERROR(IF(INDEX('HMM Locations'!$C:$G,MATCH(F43,'HMM Locations'!$A:$A,0),D43)="","(not assigned)",INDEX('HMM Locations'!$C:$G,MATCH(F43,'HMM Locations'!$A:$A,0),D43)),"(not assigned)") | J43: =IF(COUNTIF(G43:I43,"(not assigned)")=0,"Ready","Needs grid entry") | L43: 很
A44: 后 | B44: 1 | C44: hòu | D44: 4 | E44: H | F44: OU | G44: =IFERROR(IF(INDEX('HMM Actors'!$B:$B,MATCH(E44,'HMM Actors'!$A:$A,0))="","(not assigned)",INDEX('HMM Actors'!$B:$B,MATCH(E44,'HMM Actors'!$A:$A,0))),"(not assigned)") | H44: =IFERROR(IF(INDEX('HMM Locations'!$B:$B,MATCH(F44,'HMM Locations'!$A:$A,0))="","(not assigned)",INDEX('HMM Locations'!$B:$B,MATCH(F44,'HMM Locations'!$A:$A,0))),"(not assigned)") | I44: =IFERROR(IF(INDEX('HMM Locations'!$C:$G,MATCH(F44,'HMM Locations'!$A:$A,0),D44)="","(not assigned)",INDEX('HMM Locations'!$C:$G,MATCH(F44,'HMM Locations'!$A:$A,0),D44)),"(not assigned)") | J44: =IF(COUNTIF(G44:I44,"(not assigned)")=0,"Ready","Needs grid entry") | L44: 后面、后来、然后、最后
A45: 候 | B45: 1 | C45: hòu | D45: 4 | E45: H | F45: OU | G45: =IFERROR(IF(INDEX('HMM Actors'!$B:$B,MATCH(E45,'HMM Actors'!$A:$A,0))="","(not assigned)",INDEX('HMM Actors'!$B:$B,MATCH(E45,'HMM Actors'!$A:$A,0))),"(not assigned)") | H45: =IFERROR(IF(INDEX('HMM Locations'!$B:$B,MATCH(F45,'HMM Locations'!$A:$A,0))="","(not assigned)",INDEX('HMM Locations'!$B:$B,MATCH(F45,'HMM Locations'!$A:$A,0))),"(not assigned)") | I45: =IFERROR(IF(INDEX('HMM Locations'!$C:$G,MATCH(F45,'HMM Locations'!$A:$A,0),D45)="","(not assigned)",INDEX('HMM Locations'!$C:$G,MATCH(F45,'HMM Locations'!$A:$A,0),D45)),"(not assigned)") | J45: =IF(COUNTIF(G45:I45,"(not assigned)")=0,"Ready","Needs grid entry") | L45: 时候
A46: 话 | B46: 1 | C46: huà | D46: 4 | E46: H | F46: UA | G46: =IFERROR(IF(INDEX('HMM Actors'!$B:$B,MATCH(E46,'HMM Actors'!$A:$A,0))="","(not assigned)",INDEX('HMM Actors'!$B:$B,MATCH(E46,'HMM Actors'!$A:$A,0))),"(not assigned)") | H46: =IFERROR(IF(INDEX('HMM Locations'!$B:$B,MATCH(F46,'HMM Locations'!$A:$A,0))="","(not assigned)",INDEX('HMM Locations'!$B:$B,MATCH(F46,'HMM Locations'!$A:$A,0))),"(not assigned)") | I46: =IFERROR(IF(INDEX('HMM Locations'!$C:$G,MATCH(F46,'HMM Locations'!$A:$A,0),D46)="","(not assigned)",INDEX('HMM Locations'!$C:$G,MATCH(F46,'HMM Locations'!$A:$A,0),D46)),"(not assigned)") | J46: =IF(COUNTIF(G46:I46,"(not assigned)")=0,"Ready","Needs grid entry") | L46: 打电话、说话
A47: 欢 | B47: 1 | C47: huān | D47: 1 | E47: H | F47: UAN (14th, Jacob-specific) | G47: =IFERROR(IF(INDEX('HMM Actors'!$B:$B,MATCH(E47,'HMM Actors'!$A:$A,0))="","(not assigned)",INDEX('HMM Actors'!$B:$B,MATCH(E47,'HMM Actors'!$A:$A,0))),"(not assigned)") | H47: =IFERROR(IF(INDEX('HMM Locations'!$B:$B,MATCH(F47,'HMM Locations'!$A:$A,0))="","(not assigned)",INDEX('HMM Locations'!$B:$B,MATCH(F47,'HMM Locations'!$A:$A,0))),"(not assigned)") | I47: =IFERROR(IF(INDEX('HMM Locations'!$C:$G,MATCH(F47,'HMM Locations'!$A:$A,0),D47)="","(not assigned)",INDEX('HMM Locations'!$C:$G,MATCH(F47,'HMM Locations'!$A:$A,0),D47)),"(not assigned)") | J47: =IF(COUNTIF(G47:I47,"(not assigned)")=0,"Ready","Needs grid entry") | L47: 喜欢、欢迎
A48: 回 | B48: 1 | C48: huí | D48: 2 | E48: H | F48: UI | G48: =IFERROR(IF(INDEX('HMM Actors'!$B:$B,MATCH(E48,'HMM Actors'!$A:$A,0))="","(not assigned)",INDEX('HMM Actors'!$B:$B,MATCH(E48,'HMM Actors'!$A:$A,0))),"(not assigned)") | H48: =IFERROR(IF(INDEX('HMM Locations'!$B:$B,MATCH(F48,'HMM Locations'!$A:$A,0))="","(not assigned)",INDEX('HMM Locations'!$B:$B,MATCH(F48,'HMM Locations'!$A:$A,0))),"(not assigned)") | I48: =IFERROR(IF(INDEX('HMM Locations'!$C:$G,MATCH(F48,'HMM Locations'!$A:$A,0),D48)="","(not assigned)",INDEX('HMM Locations'!$C:$G,MATCH(F48,'HMM Locations'!$A:$A,0),D48)),"(not assigned)") | J48: =IF(COUNTIF(G48:I48,"(not assigned)")=0,"Ready","Needs grid entry") | L48: 回、回答
A49: 会 | B49: 1 | C49: huì | D49: 4 | E49: H | F49: UI | G49: =IFERROR(IF(INDEX('HMM Actors'!$B:$B,MATCH(E49,'HMM Actors'!$A:$A,0))="","(not assigned)",INDEX('HMM Actors'!$B:$B,MATCH(E49,'HMM Actors'!$A:$A,0))),"(not assigned)") | H49: =IFERROR(IF(INDEX('HMM Locations'!$B:$B,MATCH(F49,'HMM Locations'!$A:$A,0))="","(not assigned)",INDEX('HMM Locations'!$B:$B,MATCH(F49,'HMM Locations'!$A:$A,0))),"(not assigned)") | I49: =IFERROR(IF(INDEX('HMM Locations'!$C:$G,MATCH(F49,'HMM Locations'!$A:$A,0),D49)="","(not assigned)",INDEX('HMM Locations'!$C:$G,MATCH(F49,'HMM Locations'!$A:$A,0),D49)),"(not assigned)") | J49: =IF(COUNTIF(G49:I49,"(not assigned)")=0,"Ready","Needs grid entry") | L49: 会、会议、机会、一会儿
A50: 机 | B50: 1 | C50: jī | D50: 1 | E50: J | F50: I | G50: =IFERROR(IF(INDEX('HMM Actors'!$B:$B,MATCH(E50,'HMM Actors'!$A:$A,0))="","(not assigned)",INDEX('HMM Actors'!$B:$B,MATCH(E50,'HMM Actors'!$A:$A,0))),"(not assigned)") | H50: =IFERROR(IF(INDEX('HMM Locations'!$B:$B,MATCH(F50,'HMM Locations'!$A:$A,0))="","(not assigned)",INDEX('HMM Locations'!$B:$B,MATCH(F50,'HMM Locations'!$A:$A,0))),"(not assigned)") | I50: =IFERROR(IF(INDEX('HMM Locations'!$C:$G,MATCH(F50,'HMM Locations'!$A:$A,0),D50)="","(not assigned)",INDEX('HMM Locations'!$C:$G,MATCH(F50,'HMM Locations'!$A:$A,0),D50)),"(not assigned)") | J50: =IF(COUNTIF(G50:I50,"(not assigned)")=0,"Ready","Needs grid entry") | L50: 飞机、机场、手机、机会
A51: 几 | B51: 1 | C51: jǐ | D51: 3 | E51: J | F51: I | G51: =IFERROR(IF(INDEX('HMM Actors'!$B:$B,MATCH(E51,'HMM Actors'!$A:$A,0))="","(not assigned)",INDEX('HMM Actors'!$B:$B,MATCH(E51,'HMM Actors'!$A:$A,0))),"(not assigned)") | H51: =IFERROR(IF(INDEX('HMM Locations'!$B:$B,MATCH(F51,'HMM Locations'!$A:$A,0))="","(not assigned)",INDEX('HMM Locations'!$B:$B,MATCH(F51,'HMM Locations'!$A:$A,0))),"(not assigned)") | I51: =IFERROR(IF(INDEX('HMM Locations'!$C:$G,MATCH(F51,'HMM Locations'!$A:$A,0),D51)="","(not assigned)",INDEX('HMM Locations'!$C:$G,MATCH(F51,'HMM Locations'!$A:$A,0),D51)),"(not assigned)") | J51: =IF(COUNTIF(G51:I51,"(not assigned)")=0,"Ready","Needs grid entry") | K51: jī | L51: 几、几乎
A52: 家 | B52: 1 | C52: jiā | D52: 1 | E52: J | F52: IA | G52: =IFERROR(IF(INDEX('HMM Actors'!$B:$B,MATCH(E52,'HMM Actors'!$A:$A,0))="","(not assigned)",INDEX('HMM Actors'!$B:$B,MATCH(E52,'HMM Actors'!$A:$A,0))),"(not assigned)") | H52: =IFERROR(IF(INDEX('HMM Locations'!$B:$B,MATCH(F52,'HMM Locations'!$A:$A,0))="","(not assigned)",INDEX('HMM Locations'!$B:$B,MATCH(F52,'HMM Locations'!$A:$A,0))),"(not assigned)") | I52: =IFERROR(IF(INDEX('HMM Locations'!$C:$G,MATCH(F52,'HMM Locations'!$A:$A,0),D52)="","(not assigned)",INDEX('HMM Locations'!$C:$G,MATCH(F52,'HMM Locations'!$A:$A,0),D52)),"(not assigned)") | J52: =IF(COUNTIF(G52:I52,"(not assigned)")=0,"Ready","Needs grid entry") | L52: 家、大家、国家
A53: 见 | B53: 1 | C53: jiàn | D53: 4 | E53: J | F53: IAN | G53: =IFERROR(IF(INDEX('HMM Actors'!$B:$B,MATCH(E53,'HMM Actors'!$A:$A,0))="","(not assigned)",INDEX('HMM Actors'!$B:$B,MATCH(E53,'HMM Actors'!$A:$A,0))),"(not assigned)") | H53: =IFERROR(IF(INDEX('HMM Locations'!$B:$B,MATCH(F53,'HMM Locations'!$A:$A,0))="","(not assigned)",INDEX('HMM Locations'!$B:$B,MATCH(F53,'HMM Locations'!$A:$A,0))),"(not assigned)") | I53: =IFERROR(IF(INDEX('HMM Locations'!$C:$G,MATCH(F53,'HMM Locations'!$A:$A,0),D53)="","(not assigned)",INDEX('HMM Locations'!$C:$G,MATCH(F53,'HMM Locations'!$A:$A,0),D53)),"(not assigned)") | J53: =IF(COUNTIF(G53:I53,"(not assigned)")=0,"Ready","Needs grid entry") | L53: 看见、再见、见面
A54: 叫 | B54: 1 | C54: jiào | D54: 4 | E54: J | F54: IAO | G54: =IFERROR(IF(INDEX('HMM Actors'!$B:$B,MATCH(E54,'HMM Actors'!$A:$A,0))="","(not assigned)",INDEX('HMM Actors'!$B:$B,MATCH(E54,'HMM Actors'!$A:$A,0))),"(not assigned)") | H54: =IFERROR(IF(INDEX('HMM Locations'!$B:$B,MATCH(F54,'HMM Locations'!$A:$A,0))="","(not assigned)",INDEX('HMM Locations'!$B:$B,MATCH(F54,'HMM Locations'!$A:$A,0))),"(not assigned)") | I54: =IFERROR(IF(INDEX('HMM Locations'!$C:$G,MATCH(F54,'HMM Locations'!$A:$A,0),D54)="","(not assigned)",INDEX('HMM Locations'!$C:$G,MATCH(F54,'HMM Locations'!$A:$A,0),D54)),"(not assigned)") | J54: =IF(COUNTIF(G54:I54,"(not assigned)")=0,"Ready","Needs grid entry") | L54: 叫
A55: 姐 | B55: 1 | C55: jiě | D55: 3 | E55: J | F55: IE | G55: =IFERROR(IF(INDEX('HMM Actors'!$B:$B,MATCH(E55,'HMM Actors'!$A:$A,0))="","(not assigned)",INDEX('HMM Actors'!$B:$B,MATCH(E55,'HMM Actors'!$A:$A,0))),"(not assigned)") | H55: =IFERROR(IF(INDEX('HMM Locations'!$B:$B,MATCH(F55,'HMM Locations'!$A:$A,0))="","(not assigned)",INDEX('HMM Locations'!$B:$B,MATCH(F55,'HMM Locations'!$A:$A,0))),"(not assigned)") | I55: =IFERROR(IF(INDEX('HMM Locations'!$C:$G,MATCH(F55,'HMM Locations'!$A:$A,0),D55)="","(not assigned)",INDEX('HMM Locations'!$C:$G,MATCH(F55,'HMM Locations'!$A:$A,0),D55)),"(not assigned)") | J55: =IF(COUNTIF(G55:I55,"(not assigned)")=0,"Ready","Needs grid entry") | L55: 小姐、姐姐
A56: 今 | B56: 1 | C56: jīn | D56: 1 | E56: J | F56: IN | G56: =IFERROR(IF(INDEX('HMM Actors'!$B:$B,MATCH(E56,'HMM Actors'!$A:$A,0))="","(not assigned)",INDEX('HMM Actors'!$B:$B,MATCH(E56,'HMM Actors'!$A:$A,0))),"(not assigned)") | H56: =IFERROR(IF(INDEX('HMM Locations'!$B:$B,MATCH(F56,'HMM Locations'!$A:$A,0))="","(not assigned)",INDEX('HMM Locations'!$B:$B,MATCH(F56,'HMM Locations'!$A:$A,0))),"(not assigned)") | I56: =IFERROR(IF(INDEX('HMM Locations'!$C:$G,MATCH(F56,'HMM Locations'!$A:$A,0),D56)="","(not assigned)",INDEX('HMM Locations'!$C:$G,MATCH(F56,'HMM Locations'!$A:$A,0),D56)),"(not assigned)") | J56: =IF(COUNTIF(G56:I56,"(not assigned)")=0,"Ready","Needs grid entry") | L56: 今天
A57: 京 | B57: 1 | C57: jīng | D57: 1 | E57: J | F57: ING | G57: =IFERROR(IF(INDEX('HMM Actors'!$B:$B,MATCH(E57,'HMM Actors'!$A:$A,0))="","(not assigned)",INDEX('HMM Actors'!$B:$B,MATCH(E57,'HMM Actors'!$A:$A,0))),"(not assigned)") | H57: =IFERROR(IF(INDEX('HMM Locations'!$B:$B,MATCH(F57,'HMM Locations'!$A:$A,0))="","(not assigned)",INDEX('HMM Locations'!$B:$B,MATCH(F57,'HMM Locations'!$A:$A,0))),"(not assigned)") | I57: =IFERROR(IF(INDEX('HMM Locations'!$C:$G,MATCH(F57,'HMM Locations'!$A:$A,0),D57)="","(not assigned)",INDEX('HMM Locations'!$C:$G,MATCH(F57,'HMM Locations'!$A:$A,0),D57)),"(not assigned)") | J57: =IF(COUNTIF(G57:I57,"(not assigned)")=0,"Ready","Needs grid entry") | L57: 北京
...

Sheet HMM Actors
A1: Initial | B1: Actor | C1: Notes
A2: M | B2: Madonna
A3: K | B3: Kevin (Home Alone)
A4: G | B4: George Clooney
A5: B | B5: Brenda Felix
A6: X | B6: Cher
A7: XI | B7: Jennifer Coolidge | C7: Not used by this cross-reference: xi- syllables go to X (Cher). Remove or repurpose.
A8: W | B8: Willy Wonka
A9: Y | B9: Weird Al
A10: N | B10: Nhi Le
A11: D | B11: Denzil Hurt
A12: L | B12: Laura
A13: ZH | B13: Judge Judy
A14: SH | B14: Shannon
A15: P | B15: Prince
A16: F | B16: Fran Drescher
A17: T | B17: Taylor Swift
A18: H | B18: Hugh Jackman
A19: J | B19: Julia Roberts
... A25: S | B25: Sandra Bullock
A26: Ø | C26: Actor for syllables with no initial (ài, ān, ér, ō …). Fill in.

Sheet HMM Locations
A1: Final | B1: Set (Location) | C1: Tone 1 area | D1: Tone 2 area | E1: Tone 3 area | F1: Tone 4 area | G1: Neutral tone area | I1: Yellow cells are empty grid slots. Fill them in and the Unique Hanzi sheet updates automatically.
A2: Ø (no final) | B2: Karlštejn Castle | C2: Gatehouse | D2: Great Tower | E2: Chapel of the Holy Cross | F2: Dungeon
A3: A | B3: Praha | C3: Charles Bridge | D3: Castle courtyard | E3: Wenceslas Square | F3: Vltava riverbank
A4: O | B4: Costco | C4: Food court | D4: Warehouse aisles | E4: Checkout line | F4: Parking lot
A5: E | B5: Jacob's parents' place | C5: Living room | D5: Kitchen | E5: Garage | F5: Backyard
A6: AI | B6: Sky3 | C6: Rooftop kitchen — kāi 开 | D6: Gym / fitness room | E6: Lobby — mǎi 买 | F6: Elevator bank
A7: EI | B7: Safeway | C7: Produce section | D7: Deli counter | E7: Checkout | F7: Wine checkout lane
A8: AO | B8: Nashville townhouse | C8: Front porch | D8: Kitchen | E8: Upstairs bedroom | F8: Living room — yào 要
A9: OU | B9: Hluboká Castle | C9: Courtyard | D9: Library | E9: Tower | F9: Moat/garden
A10: AN | B10: Anděl | C10: Metro station | D10: Shopping mall | E10: Street corner | F10: Tram stop
A11: ANG | B11: Jacob's current apartment | C11: Office — bāng 帮 | D11: Kitchen — máng 忙 | E11: Bathroom — xiǎng 想 | F11: Bedroom — wàng 忘
A12: (E)N | B12: Aberdeen | C12: Harbor | D12: High street | E12: Train station | F12: University
A13: (E)NG | B13: Old Town Square | C13: Trdelník stand | D13: Astronomical Clock — néng 能 | E13: Jan Hus statue — děng 等 | F13: Týn chapel
... A15: UAN (14th, Jacob-specific) | B15: Nike campus – Boston building | C15: The Half Pipe (biggest meeting room) | D15: Jacob's desk | E15: The front lobby | F15: The toe rail ("toe nail")
A16: I
A17: U
A18: IAN
A19: ING
A20: IAO
A21: UO
A22: IE
A23: IN
A24: IU
A25: UI
A26: IANG
A27: UA
... A35: IONG
